<?xml version="1.0" encoding="UTF-8"?>
<testng-results skipped="0" failed="1" total="3" passed="2">
  <reporter-output>
  </reporter-output>
  <suite name="Default suite" duration-ms="77" started-at="2018-09-10T21:16:11Z" finished-at="2018-09-10T21:16:11Z">
    <groups>
    </groups>
    <test name="Default test" duration-ms="77" started-at="2018-09-10T21:16:11Z" finished-at="2018-09-10T21:16:11Z">
      <class name="com.qa.tests.LoginTest">
        <test-method status="PASS" signature="Logintest()[pri:0, instance:com.qa.tests.LoginTest@68be2bc2]" name="Logintest" duration-ms="24" started-at="2018-09-10T23:16:11Z" finished-at="2018-09-10T23:16:11Z">
          <reporter-output>
          </reporter-output>
        </test-method> <!-- Logintest -->
        <test-method status="PASS" signature="Logintest1()[pri:0, instance:com.qa.tests.LoginTest@68be2bc2]" name="Logintest1" duration-ms="3" started-at="2018-09-10T23:16:11Z" finished-at="2018-09-10T23:16:11Z">
          <reporter-output>
          </reporter-output>
        </test-method> <!-- Logintest1 -->
        <test-method status="FAIL" signature="Logintest2()[pri:0, instance:com.qa.tests.LoginTest@68be2bc2]" name="Logintest2" duration-ms="4" started-at="2018-09-10T23:16:11Z" finished-at="2018-09-10T23:16:11Z">
          <exception class="java.lang.AssertionError">
            <message>
              <![CDATA[expected [true] but found [false]]]>
            </message>
            <full-stacktrace>
              <![CDATA[java.lang.AssertionError: expected [true] but found [false]
	at org.testng.Assert.fail(Assert.java:94)
	at org.testng.Assert.failNotEquals(Assert.java:494)
	at org.testng.Assert.assertTrue(Assert.java:42)
	at org.testng.Assert.assertTrue(Assert.java:52)
	at com.qa.tests.LoginTest.Logintest2(LoginTest.java:22)
	at sun.reflect.NativeMethodAccessorImpl.invoke0(Native Method)
	at sun.reflect.NativeMethodAccessorImpl.invoke(Unknown Source)
	at sun.reflect.DelegatingMethodAccessorImpl.invoke(Unknown Source)
	at java.lang.reflect.Method.invoke(Unknown Source)
	at org.testng.internal.MethodInvocationHelper.invokeMethod(MethodInvocationHelper.java:80)
	at org.testng.internal.Invoker.invokeMethod(Invoker.java:714)
	at org.testng.internal.Invoker.invokeTestMethod(Invoker.java:901)
	at org.testng.internal.Invoker.invokeTestMethods(Invoker.java:1231)
	at org.testng.internal.TestMethodWorker.invokeTestMethods(TestMethodWorker.java:127)
	at org.testng.internal.TestMethodWorker.run(TestMethodWorker.java:111)
	at org.testng.TestRunner.privateRun(TestRunner.java:767)
	at org.testng.TestRunner.run(TestRunner.java:617)
	at org.testng.SuiteRunner.runTest(SuiteRunner.java:334)
	at org.testng.SuiteRunner.runSequentially(SuiteRunner.java:329)
	at org.testng.SuiteRunner.privateRun(SuiteRunner.java:291)
	at org.testng.SuiteRunner.run(SuiteRunner.java:240)
	at org.testng.SuiteRunnerWorker.runSuite(SuiteRunnerWorker.java:52)
	at org.testng.SuiteRunnerWorker.run(SuiteRunnerWorker.java:86)
	at org.testng.TestNG.runSuitesSequentially(TestNG.java:1198)
	at org.testng.TestNG.runSuitesLocally(TestNG.java:1123)
	at org.testng.TestNG.run(TestNG.java:1031)
	at org.testng.remote.AbstractRemoteTestNG.run(AbstractRemoteTestNG.java:114)
	at org.testng.remote.RemoteTestNG.initAndRun(RemoteTestNG.java:251)
	at org.testng.remote.RemoteTestNG.main(RemoteTestNG.java:77)
]]>
            </full-stacktrace>
          </exception> <!-- java.lang.AssertionError -->
          <reporter-output>
          </reporter-output>
        </test-method> <!-- Logintest2 -->
      </class> <!-- com.qa.tests.LoginTest -->
    </test> <!-- Default test -->
  </suite> <!-- Default suite -->
</testng-results>
